<?xml version="1.0" encoding="UTF-8"?>
<sdf version="1.10">
  <model name="b3rb">
    <self_collide>false</self_collide>
    <static>false</static>
    <link name="base_link">
      <pose>0 0 0.04 0 0 0</pose>
      <inertial>
        <pose>0 0 0 0 0 0</pose>
        <mass>3.0</mass>
        <inertia>
          <ixx>0.0054</ixx>
          <ixy>0</ixy>
          <ixz>0</ixz>
          <iyy>0.0252</iyy>
          <iyz>0</iyz>
          <izz>0.0252</izz>
        </inertia>
      </inertial>
      <visual name="NXP_LOGO">
        <pose>0.1 0.0 .1275 0 0 -1.5707</pose>
        <cast_shadows>false</cast_shadows>
        <geometry>
          <plane>
            <normal>0 0 1</normal>
            <size>.075 .075</size>
          </plane>
        </geometry>
        <material>
          <diffuse>1.0 1.0 1.0</diffuse>
          <specular>1.0 1.0 1.0</specular>
          <pbr>
            <metal>
              <albedo_map>model://b3rb/materials/textures/NXP.png</albedo_map>
            </metal>
          </pbr>
        </material>
      </visual>
      <visual name="CogniPilot_LOGO">
        <pose>-0.1 0.0 .1277 0 0 -1.5707</pose>
        <cast_shadows>false</cast_shadows>
        <geometry>
          <plane>
            <normal>0 0 1</normal>
            <size>0.08652 0.04584</size>
          </plane>
        </geometry>
        <material>
          <diffuse>1.0 1.0 1.0</diffuse>
          <specular>1.0 1.0 1.0</specular>
          <pbr>
            <metal>
              <albedo_map>model://b3rb/materials/textures/CogniPilot.png</albedo_map>
            </metal>
          </pbr>
        </material>
      </visual>
      <visual name="BaseVisual">
        <pose>0.002 0 -0.005 0 0 -1.5707</pose>
        <geometry>
          <mesh>
            <uri>model://b3rb/meshes/b3rb.dae</uri>
          </mesh>
        </geometry>
      </visual>
      <collision name="BaseCollision">
        <pose>0 0 .06 0 0 0</pose>
        <geometry>
          <box>
            <size>.34 .09 .14</size>
          </box>
        </geometry>
      </collision>
    </link>
    <link name="base_footprint"/>
    <link name="sensors">
      <pose>0 0 0 0 0 0</pose>
      <inertial>
        <pose>0 0 0 0 0 0</pose>
        <mass>0.0000001</mass>
        <inertia>
          <ixx>0.000000000001</ixx>
          <ixy>0</ixy>
          <ixz>0</ixz>
          <iyy>0.000000000001</iyy>
          <iyz>0</iyz>
          <izz>0.000000000001</izz>
        </inertia>
      </inertial>
      <sensor name="imu_sensor" type="imu">
        <always_on>1</always_on>
        <update_rate>250</update_rate>
      </sensor>
      <sensor name="mag_sensor" type="magnetometer">
        <always_on>1</always_on>
        <update_rate>50</update_rate>
      </sensor>
      <sensor name="altimeter_sensor" type="altimeter">
        <always_on>1</always_on>
        <update_rate>50</update_rate>
      </sensor>
      <sensor name="navsat_sensor" type="navsat">
        <always_on>1</always_on>
        <update_rate>10</update_rate>
        <navsat>
          <position_sensing></position_sensing>
          <velocity_sensing></velocity_sensing>
        </navsat>
      </sensor>
    </link>
    <link name="FrontRightwheel">
      <pose relative_to="FrontRightwheelJoint">0 0 0 0 0 0</pose>
      <inertial>
        <mass>.05</mass>
        <inertia>
          <ixx>0.00003331</ixx>
          <ixy>0</ixy>
          <ixz>0</ixz>
          <iyy>0.0000204</iyy>
          <iyz>0</iyz>
          <izz>0.0000204</izz>
        </inertia>
      </inertial>
      <gravity>true</gravity>
      <velocity_decay/>
      <visual name="FrontRightwheelVisual">
        <pose>0 0 0 0 0 0</pose>
        <geometry>
          <mesh>
            <uri>model://b3rb/meshes/wheel.dae</uri>
          </mesh>
        </geometry>
      </visual>
      <collision name="FrontRightwheelCollision">
        <pose>0 .015 0 -1.5707 0 0</pose>
        <geometry>
          <cylinder>
            <length>0.03</length>
            <radius>0.0365</radius>
          </cylinder>
        </geometry>
        <surface>
          <friction>
            <ode>
              <mu>1.0</mu>
              <mu2>0.5</mu2>
              <fdir1>0 0 1</fdir1>
            </ode>
          </friction>
        </surface>
      </collision>
    </link>
    <link name="FrontRightwheelSteering">
      <pose relative_to="FrontRightwheelSteeringJoint">0 0 0 0 0 0</pose>
      <inertial>
        <mass>0.005</mass>
        <inertia>
          <ixx>0.0000018</ixx>
          <iyy>0.0000018</iyy>
          <izz>0.0000018</izz>
        </inertia>
      </inertial>
    </link>
    <link name="FrontLeftwheel">
      <pose relative_to="FrontLeftwheelJoint">0 0 0 0 0 0</pose>
      <inertial>
        <mass>.05</mass>
        <inertia>
          <ixx>0.00003331</ixx>
          <ixy>0</ixy>
          <ixz>0</ixz>
          <iyy>0.0000204</iyy>
          <iyz>0</iyz>
          <izz>0.0000204</izz>
        </inertia>
      </inertial>
      <gravity>true</gravity>
      <velocity_decay/>
      <visual name="FrontLeftwheelVisual">
        <pose>0 0 0 0 0 3.14159</pose>
        <geometry>
          <mesh>
            <uri>model://b3rb/meshes/wheel.dae</uri>
          </mesh>
        </geometry>
      </visual>
      <collision name="FrontLeftwheelCollision">
        <pose>0 -.015 0 -1.5707 0 0</pose>
        <geometry>
          <cylinder>
            <length>0.03</length>
            <radius>0.0365</radius>
          </cylinder>
        </geometry>
        <surface>
          <friction>
            <ode>
              <mu>1.0</mu>
              <mu2>0.5</mu2>
              <fdir1>0 0 1</fdir1>
            </ode>
          </friction>
        </surface>
      </collision>
    </link>
    <link name="FrontLeftwheelSteering">
      <pose relative_to="FrontLeftwheelSteeringJoint">0 0 0 0 0 0</pose>
      <inertial>
        <mass>0.005</mass>
        <inertia>
          <ixx>0.0000018</ixx>
          <iyy>0.0000018</iyy>
          <izz>0.0000018</izz>
        </inertia>
      </inertial>
    </link>
    <link name="RearRightwheel">
      <pose relative_to="RearRightwheelJoint">0 0 0 0 0 0</pose>
      <inertial>
        <mass>.05</mass>
        <inertia>
          <ixx>0.00003331</ixx>
          <ixy>0</ixy>
          <ixz>0</ixz>
          <iyy>0.0000204</iyy>
          <iyz>0</iyz>
          <izz>0.0000204</izz>
        </inertia>
      </inertial>
      <gravity>true</gravity>
      <velocity_decay/>
      <visual name="RearRightwheelVisual">
        <pose>0 0 0 0 0 0</pose>
        <geometry>
          <mesh>
            <uri>model://b3rb/meshes/wheel.dae</uri>
          </mesh>
        </geometry>
      </visual>
      <collision name="RearRightwheelCollision">
        <pose>0 .015 0 -1.5707 0 0</pose>
        <geometry>
          <cylinder>
            <length>0.03</length>
            <radius>0.0365</radius>
          </cylinder>
        </geometry>
        <surface>
          <friction>
            <ode>
              <mu>1.0</mu>
              <mu2>0.5</mu2>
              <fdir1>0 0 1</fdir1>
            </ode>
          </friction>
        </surface>
      </collision>
    </link>
    <link name="RearLeftwheel">
      <pose relative_to="RearLeftwheelJoint">0 0 0 0 0 0</pose>
      <inertial>
        <mass>.05</mass>
        <inertia>
          <ixx>0.00003331</ixx>
          <ixy>0</ixy>
          <ixz>0</ixz>
          <iyy>0.0000204</iyy>
          <iyz>0</iyz>
          <izz>0.0000204</izz>
        </inertia>
      </inertial>
      <gravity>true</gravity>
      <velocity_decay/>
      <visual name="RearLeftwheelVisual">
        <pose>0 0 0 0 0 3.14159</pose>
        <geometry>
          <mesh>
            <uri>model://b3rb/meshes/wheel.dae</uri>
          </mesh>
        </geometry>
      </visual>
      <collision name="RearLeftwheelCollision">
        <pose>0 -.015 0 -1.5707 0 0</pose>
        <geometry>
          <cylinder>
            <length>0.03</length>
            <radius>0.0365</radius>
          </cylinder>
        </geometry>
        <surface>
          <friction>
            <ode>
              <mu>1.0</mu>
              <mu2>0.5</mu2>
              <fdir1>0 0 1</fdir1>
            </ode>
          </friction>
        </surface>
      </collision>
    </link>
    <link name="camera_link">
      <pose>.173 0 .15 0 0 0</pose>
      <inertial>
        <pose>0 0 0 0 0 0</pose>
        <mass>0.01</mass>
        <inertia>
          <ixx>0.00000130666</ixx> <!-- (.01/12)*(.028^2+.028^2) -->
          <ixy>0</ixy>
          <ixz>0</ixz>
          <iyy>0.00000130666</iyy> <!-- (.01/12)*(.028^2+.028^2) -->
          <iyz>0</iyz>
          <izz>0.00000130666</izz> <!-- (.01/12)*(.028^2+.028^2) -->
        </inertia>
      </inertial>
      <visual name="camera_housing">
        <pose>.013 0 0 0 0 0</pose>
        <geometry>
          <box>
            <size>.008 .028 .028</size>
          </box>
        </geometry>
        <material>
          <diffuse>1.0 1.0 1.0</diffuse>
          <specular>1.0 1.0 1.0</specular>
        </material>
      </visual>
      <visual name="camera_housing_mount">
        <pose>.008 0 0 0 0 0</pose>
        <geometry>
          <box>
            <size>.008 .014 .01</size>
          </box>
        </geometry>
        <material>
          <diffuse>1.0 1.0 1.0</diffuse>
          <specular>1.0 1.0 1.0</specular>
        </material>
      </visual>
      <visual name="camera_lens">
        <pose>.016 0 .006 0 1.57079632679 0</pose>
        <geometry>
          <cylinder>
            <length>0.003</length>
            <radius>0.004</radius>
          </cylinder>
        </geometry>
      </visual>
      <sensor name="ov5645" type="camera">
        <pose>.016 0 .006 0 0 0</pose>
        <camera>
          <image>
            <width>320</width>
            <height>240</height>
            <format>B8G8R8</format>
          </image>
          <clip>
            <near>0.05</near>
            <far>100</far>
          </clip>
          <optical_frame_id>camera_link_optical</optical_frame_id>
        </camera>
        <always_on>1</always_on>
        <update_rate>30</update_rate>
        <visualize>true</visualize>
        <topic>/camera/image_raw</topic>
      </sensor>
    </link>
    <link name="lidar_link">
      <pose>0 0 .195 0 0 0</pose>
      <inertial>
        <pose>0 0 0 0 0 0</pose>
        <mass>0.17</mass>
        <inertia>
          <ixx>0.0001926666667</ixx> <!-- (.17/12)*(.1^2+.06^2) -->
          <ixy>0</ixy>
          <ixz>0</ixz>
          <iyy>0.0001224141667</iyy> <!-- (.17/12)*(.071^2+.06^2) -->
          <iyz>0</iyz>
          <izz>0.0002130808333</izz> <!-- (.17/12)*(.071^2+.1^2) -->
        </inertia>
      </inertial>
      <visual name="visual_box">
        <pose>0 0 -.017 0 0 0</pose>
        <geometry>
          <box>
            <size>0.039 0.039 0.022</size>
          </box>
        </geometry>
        <material>
          <diffuse>0.01 0.01 0.01</diffuse>
          <specular>0.01 0.01 0.01</specular>
        </material>
      </visual>
      <visual name="visual_cylinder">
        <pose>0 0 0 0 0 0</pose>
        <geometry>
          <cylinder>
            <radius>0.018</radius>
            <length>0.014</length>
          </cylinder>
        </geometry>
        <material>
          <diffuse>0.01 0.01 0.01</diffuse>
          <specular>0.01 0.01 0.01</specular>
        </material>
      </visual>
      <sensor name="lidar" type="gpu_lidar">
        <lidar>
          <scan>
            <horizontal>
              <samples>360</samples>
              <resolution>1</resolution>
              <min_angle>-3.14159265359</min_angle>
              <max_angle>3.14159265359</max_angle>
            </horizontal>
          </scan>
          <range>
            <min>0.15</min>
            <max>10</max>
            <resolution>0.01</resolution>
          </range>
        </lidar>
        <gz_frame_id>lidar_link</gz_frame_id>
        <alwaysOn>1</alwaysOn>
        <visualize>false</visualize>
        <update_rate>10</update_rate>
      </sensor>
    </link>
    <joint name="camera_joint" type="fixed">
      <parent>base_link</parent>
      <child>camera_link</child>
    </joint>
    <joint name="lidar_joint" type="fixed">
      <parent>base_link</parent>
      <child>lidar_link</child>
    </joint>
    <joint name="FrontRightwheelSteeringJoint" type="revolute">
      <parent>base_link</parent>
      <child>FrontRightwheelSteering</child>
      <pose relative_to="base_link">.112 -.10 0 0 0 0</pose>
      <axis>
        <xyz>0 0 1</xyz>
        <limit>
          <lower>-0.6</lower>
          <upper>0.6</upper>
          <velocity>1000</velocity>
          <effort>1000</effort>
        </limit>
      </axis>
    </joint>

    <joint name="FrontRightwheelJoint" type="revolute">
      <parent>FrontRightwheelSteering</parent>
      <child>FrontRightwheel</child>
      <pose relative_to="FrontRightwheelSteeringJoint">0 0 0 0 0 0</pose>
      <axis>
        <xyz>0 1 0</xyz>
        <limit>
          <lower>-1.79769e+308</lower>
          <upper>1.79769e+308</upper>
        </limit>
        <dynamics>
          <spring_reference>0</spring_reference>
          <spring_stiffness>0</spring_stiffness>
        </dynamics>
      </axis>
    </joint>
    <joint name="FrontLeftwheelSteeringJoint" type="revolute">
      <parent>base_link</parent>
      <child>FrontLeftwheelSteering</child>
      <pose relative_to="base_link">.112 .10 0 0 0 0</pose>
      <axis>
        <xyz>0 0 1</xyz>
        <limit>
          <lower>-0.6</lower>
          <upper>0.6</upper>
          <velocity>1000</velocity>
          <effort>1000</effort>
        </limit>
      </axis>
    </joint>
    <joint name="FrontLeftwheelJoint" type="revolute">
      <parent>FrontLeftwheelSteering</parent>
      <child>FrontLeftwheel</child>
      <pose relative_to="FrontLeftwheelSteeringJoint">0 0 0 0 0 0</pose>
      <axis>
        <xyz>0 1 0</xyz>
        <limit>
          <lower>-1.79769e+308</lower>
          <upper>1.79769e+308</upper>
        </limit>
        <dynamics>
          <spring_reference>0</spring_reference>
          <spring_stiffness>0</spring_stiffness>
        </dynamics>
      </axis>
    </joint>
    <joint name="RearRightwheelJoint" type="revolute">
      <parent>base_link</parent>
      <child>RearRightwheel</child>
      <pose relative_to="base_link">-.1135 -.10 0 0 0 0</pose>
      <axis>
        <xyz>0 1 0</xyz>
        <limit>
          <lower>-1.79769e+308</lower>
          <upper>1.79769e+308</upper>
        </limit>
        <dynamics>
          <spring_reference>0</spring_reference>
          <spring_stiffness>0</spring_stiffness>
        </dynamics>
      </axis>
    </joint>
    <joint name="RearLeftwheelJoint" type="revolute">
      <parent>base_link</parent>
      <child>RearLeftwheel</child>
      <pose relative_to="base_link">-.1135 .10 0 0 0 0</pose>
      <axis>
        <xyz>0 1 0</xyz>
        <limit>
          <lower>-1.79769e+308</lower>
          <upper>1.79769e+308</upper>
        </limit>
        <dynamics>
          <spring_reference>0</spring_reference>
          <spring_stiffness>0</spring_stiffness>
        </dynamics>
      </axis>
    </joint>
    <joint name="base_joint" type="fixed">
      <parent>base_footprint</parent>
      <child>base_link</child>
      <pose>0.0 0.0 -0.04 0 0 0</pose>
    </joint>
    <joint name="SensorsJoint" type="fixed">
        <parent>base_link</parent>
        <child>sensors</child>
        <pose>0.0 0.0 0.0 0 0 0</pose>
    </joint>
    <plugin
        filename="gz-sim-joint-controller-system"
        name="gz::sim::systems::JointController">
      <joint_name>FrontLeftwheelJoint</joint_name>
      <joint_name>FrontRightwheelJoint</joint_name>
      <joint_name>RearRightwheelJoint</joint_name>
      <joint_name>RearLeftwheelJoint</joint_name>
      <use_actuator_msg>true</use_actuator_msg>
      <actuator_number>0</actuator_number>
    </plugin>
    <plugin
      filename="gz-sim-ackermann-steering-system"
      name="gz::sim::systems::AckermannSteering">
      <steering_only>true</steering_only>
      <use_actuator_msg>true</use_actuator_msg>
      <actuator_number>0</actuator_number>
      <left_steering_joint>FrontLeftwheelSteeringJoint</left_steering_joint>
      <right_steering_joint>FrontRightwheelSteeringJoint</right_steering_joint>
      <steering_limit>0.4</steering_limit>
      <steer_p_gain>10.0</steer_p_gain>
      <wheel_base>.2255</wheel_base>
      <wheel_separation>.2</wheel_separation>
    </plugin>
    <plugin
      filename="gz-sim-odometry-publisher-system"
      name="gz::sim::systems::OdometryPublisher">
      <xyz_offset>0 0 0</xyz_offset>
      <rpy_offset>0 0 0</rpy_offset>
      <gaussian_noise>0</gaussian_noise>
      <robot_base_frame>base_link</robot_base_frame>
      <dimensions>3</dimensions>
      <odom_publish_frequency>30</odom_publish_frequency>
      <odom_frame>odom</odom_frame>
    </plugin>
    <plugin
      filename="gz-sim-linearbatteryplugin-system"
      name="gz::sim::systems::LinearBatteryPlugin">
      <battery_name>linear_battery</battery_name>
      <voltage>12.6</voltage>
      <open_circuit_voltage_constant_coef>12.6</open_circuit_voltage_constant_coef>
      <open_circuit_voltage_linear_coef>-3.0</open_circuit_voltage_linear_coef>
      <initial_charge>4.8</initial_charge>
      <capacity>5.0</capacity>
      <resistance>0.07</resistance>
      <smooth_current_tau>2.0</smooth_current_tau>
      <soc_threshold>0.51</soc_threshold>
      <power_load>48.0</power_load>
      <fix_issue_225>true</fix_issue_225>
      <start_draining>true</start_draining>
    </plugin>
    <plugin
      filename="gz-sim-joint-state-publisher-system"
      name="gz::sim::systems::JointStatePublisher">
      <joint_name>RearRightwheelJoint</joint_name>
      <joint_name>RearLeftwheelJoint</joint_name>
      <joint_name>FrontRightwheelJoint</joint_name>
      <joint_name>FrontLeftwheelJoint</joint_name>
    </plugin>
    <plugin
      filename="gz-sim-joint-state-publisher-system"
      name="gz::sim::systems::JointStatePublisher">
      <joint_name>FrontRightwheelSteeringJoint</joint_name>
      <joint_name>FrontLeftwheelSteeringJoint</joint_name>
      <topic>steering</topic>
    </plugin>
  </model>
</sdf>
